<?xml version="1.0"?>
<robot name="parallel_link">
  <link name="base_link">
    <visual>
      <origin xyz="0 0 0" rpy="0 0 0" />
      <geometry>
        <box size="0.1 0.1 0.05"/>
      </geometry>
      <material name="blue">
        <color rgba="0 0 .8 1" />
      </material>
    </visual>
  </link>

  <joint name="joint0" type="continuous">
    <parent link="base_link"/>
    <child link="link1"/>
    <origin xyz="0 0 0.06" rpy="0 0 0" />
    <axis xyz="0 0 1" />
    <limit lower="-1.57" upper="1.57" effort="0.5293" velocity="6.159937255" />
  </joint>

  <link name="link1">
    <visual>
      <origin xyz="0 0 0.015" rpy="0 0 0" />
      <geometry>
        <cylinder radius="0.02" length="0.1" />
      </geometry>
      <material name="yellow">
        <color rgba=".8 0 .8 1" />
      </material>
    </visual>
  </link>

  <joint name="joint1" type="revolute">
    <parent link="link1"/>
    <child link="link2"/>
    <origin xyz="0 0 0.065" rpy="0 0 0"/>
    <axis xyz="1 0.0 0.0"/>
    <limit lower="-1.57" upper="0" effort="0.5293" velocity="6.159937255" />
  </joint>

  <link name="link2">
    <visual>
      <origin xyz="0 0 0.05" rpy="0 0 0" />
      <geometry>
        <!-- <cylinder radius="0.02" length="0.1" /> -->
        <box size="0.01 0.04 0.1"/>
      </geometry>
      <material name="blue">
        <color rgba=".1 0 .9 1" />
      </material>
    </visual>
  </link>

  <joint name="joint2" type="revolute">
    <parent link="link2"/>
    <child link="link3"/>
    <origin xyz="0 0 0.1" rpy="0 0 0"/>
    <axis xyz="1 0.0 0.0"/>
    <limit lower="-1.57" upper="1.57" effort="0.5293" velocity="6.159937255" />
    <mimic joint="joint1" multiplier="-1" offset="0" />
  </joint>

  <link name="link3">
    <visual>
      <origin xyz="0 0.025 0.005" rpy="0 1.570796326794 1.570796326794" />
      <geometry>
        <!-- <cylinder radius="0.02" length="0.1" />
         -->
         <box size="0.01 0.05 0.075"/>
      </geometry>
      <material name="blue">
        <color rgba=".9 0 .1 1" />
      </material>
    </visual>
  </link>

</robot>
